{
 "cells": [
  {
   "cell_type": "code",
   "execution_count": 5,
   "id": "87173ecd",
   "metadata": {},
   "outputs": [
    {
     "name": "stdout",
     "output_type": "stream",
     "text": [
      "Found 3055 images belonging to 36 classes.\n",
      "Found 351 images belonging to 36 classes.\n",
      "Found 364 images belonging to 37 classes.\n"
     ]
    },
    {
     "name": "stderr",
     "output_type": "stream",
     "text": [
      "C:\\Users\\VARUN-PC\\AppData\\Local\\Temp\\ipykernel_21016\\746130139.py:77: UserWarning: `Model.fit_generator` is deprecated and will be removed in a future version. Please use `Model.fit`, which supports generators.\n",
      "  model.fit_generator(\n"
     ]
    },
    {
     "name": "stdout",
     "output_type": "stream",
     "text": [
      "Epoch 1/10\n",
      " 1/96 [..............................] - ETA: 7:29 - loss: 3.5918 - accuracy: 0.0625"
     ]
    },
    {
     "name": "stderr",
     "output_type": "stream",
     "text": [
      "C:\\Python310\\lib\\site-packages\\PIL\\Image.py:959: UserWarning: Palette images with Transparency expressed in bytes should be converted to RGBA images\n",
      "  warnings.warn(\n"
     ]
    },
    {
     "name": "stdout",
     "output_type": "stream",
     "text": [
      "96/96 [==============================] - 186s 2s/step - loss: 3.8914 - accuracy: 0.0671 - val_loss: 2.9644 - val_accuracy: 0.1652\n",
      "Epoch 2/10\n",
      "96/96 [==============================] - 191s 2s/step - loss: 2.8709 - accuracy: 0.1755 - val_loss: 2.4268 - val_accuracy: 0.2650\n",
      "Epoch 3/10\n",
      "96/96 [==============================] - 180s 2s/step - loss: 2.5630 - accuracy: 0.2445 - val_loss: 2.1266 - val_accuracy: 0.3276\n",
      "Epoch 4/10\n",
      "96/96 [==============================] - 180s 2s/step - loss: 2.4289 - accuracy: 0.2795 - val_loss: 1.8386 - val_accuracy: 0.4103\n",
      "Epoch 5/10\n",
      "96/96 [==============================] - 184s 2s/step - loss: 2.3637 - accuracy: 0.3025 - val_loss: 1.8023 - val_accuracy: 0.4558\n",
      "Epoch 6/10\n",
      "96/96 [==============================] - 183s 2s/step - loss: 2.2664 - accuracy: 0.3214 - val_loss: 1.8325 - val_accuracy: 0.4444\n",
      "Epoch 7/10\n",
      "96/96 [==============================] - 180s 2s/step - loss: 2.2059 - accuracy: 0.3519 - val_loss: 1.5882 - val_accuracy: 0.5014\n",
      "Epoch 8/10\n",
      "96/96 [==============================] - 186s 2s/step - loss: 2.1365 - accuracy: 0.3689 - val_loss: 1.5801 - val_accuracy: 0.4872\n",
      "Epoch 9/10\n",
      "96/96 [==============================] - 175s 2s/step - loss: 2.1085 - accuracy: 0.3656 - val_loss: 1.6515 - val_accuracy: 0.5014\n",
      "Epoch 10/10\n",
      "96/96 [==============================] - 171s 2s/step - loss: 2.0833 - accuracy: 0.3637 - val_loss: 1.6222 - val_accuracy: 0.4986\n"
     ]
    },
    {
     "name": "stderr",
     "output_type": "stream",
     "text": [
      "C:\\Users\\VARUN-PC\\AppData\\Local\\Temp\\ipykernel_21016\\746130139.py:86: UserWarning: `Model.evaluate_generator` is deprecated and will be removed in a future version. Please use `Model.evaluate`, which supports generators.\n",
      "  score = model.evaluate_generator(\n"
     ]
    },
    {
     "ename": "InvalidArgumentError",
     "evalue": "Graph execution error:\n\nDetected at node 'categorical_crossentropy/softmax_cross_entropy_with_logits' defined at (most recent call last):\n    File \"C:\\Python310\\lib\\runpy.py\", line 196, in _run_module_as_main\n      return _run_code(code, main_globals, None,\n    File \"C:\\Python310\\lib\\runpy.py\", line 86, in _run_code\n      exec(code, run_globals)\n    File \"C:\\Python310\\lib\\site-packages\\ipykernel_launcher.py\", line 17, in <module>\n      app.launch_new_instance()\n    File \"C:\\Python310\\lib\\site-packages\\traitlets\\config\\application.py\", line 1043, in launch_instance\n      app.start()\n    File \"C:\\Python310\\lib\\site-packages\\ipykernel\\kernelapp.py\", line 725, in start\n      self.io_loop.start()\n    File \"C:\\Python310\\lib\\site-packages\\tornado\\platform\\asyncio.py\", line 215, in start\n      self.asyncio_loop.run_forever()\n    File \"C:\\Python310\\lib\\asyncio\\base_events.py\", line 600, in run_forever\n      self._run_once()\n    File \"C:\\Python310\\lib\\asyncio\\base_events.py\", line 1896, in _run_once\n      handle._run()\n    File \"C:\\Python310\\lib\\asyncio\\events.py\", line 80, in _run\n      self._context.run(self._callback, *self._args)\n    File \"C:\\Python310\\lib\\site-packages\\ipykernel\\kernelbase.py\", line 513, in dispatch_queue\n      await self.process_one()\n    File \"C:\\Python310\\lib\\site-packages\\ipykernel\\kernelbase.py\", line 502, in process_one\n      await dispatch(*args)\n    File \"C:\\Python310\\lib\\site-packages\\ipykernel\\kernelbase.py\", line 409, in dispatch_shell\n      await result\n    File \"C:\\Python310\\lib\\site-packages\\ipykernel\\kernelbase.py\", line 729, in execute_request\n      reply_content = await reply_content\n    File \"C:\\Python310\\lib\\site-packages\\ipykernel\\ipkernel.py\", line 422, in do_execute\n      res = shell.run_cell(\n    File \"C:\\Python310\\lib\\site-packages\\ipykernel\\zmqshell.py\", line 540, in run_cell\n      return super().run_cell(*args, **kwargs)\n    File \"C:\\Python310\\lib\\site-packages\\IPython\\core\\interactiveshell.py\", line 3009, in run_cell\n      result = self._run_cell(\n    File \"C:\\Python310\\lib\\site-packages\\IPython\\core\\interactiveshell.py\", line 3064, in _run_cell\n      result = runner(coro)\n    File \"C:\\Python310\\lib\\site-packages\\IPython\\core\\async_helpers.py\", line 129, in _pseudo_sync_runner\n      coro.send(None)\n    File \"C:\\Python310\\lib\\site-packages\\IPython\\core\\interactiveshell.py\", line 3269, in run_cell_async\n      has_raised = await self.run_ast_nodes(code_ast.body, cell_name,\n    File \"C:\\Python310\\lib\\site-packages\\IPython\\core\\interactiveshell.py\", line 3448, in run_ast_nodes\n      if await self.run_code(code, result, async_=asy):\n    File \"C:\\Python310\\lib\\site-packages\\IPython\\core\\interactiveshell.py\", line 3508, in run_code\n      exec(code_obj, self.user_global_ns, self.user_ns)\n    File \"C:\\Users\\VARUN-PC\\AppData\\Local\\Temp\\ipykernel_21016\\746130139.py\", line 77, in <module>\n      model.fit_generator(\n    File \"C:\\Python310\\lib\\site-packages\\keras\\engine\\training.py\", line 2636, in fit_generator\n      return self.fit(\n    File \"C:\\Python310\\lib\\site-packages\\keras\\utils\\traceback_utils.py\", line 65, in error_handler\n      return fn(*args, **kwargs)\n    File \"C:\\Python310\\lib\\site-packages\\keras\\engine\\training.py\", line 1729, in fit\n      val_logs = self.evaluate(\n    File \"C:\\Python310\\lib\\site-packages\\keras\\utils\\traceback_utils.py\", line 65, in error_handler\n      return fn(*args, **kwargs)\n    File \"C:\\Python310\\lib\\site-packages\\keras\\engine\\training.py\", line 2072, in evaluate\n      tmp_logs = self.test_function(iterator)\n    File \"C:\\Python310\\lib\\site-packages\\keras\\engine\\training.py\", line 1852, in test_function\n      return step_function(self, iterator)\n    File \"C:\\Python310\\lib\\site-packages\\keras\\engine\\training.py\", line 1836, in step_function\n      outputs = model.distribute_strategy.run(run_step, args=(data,))\n    File \"C:\\Python310\\lib\\site-packages\\keras\\engine\\training.py\", line 1824, in run_step\n      outputs = model.test_step(data)\n    File \"C:\\Python310\\lib\\site-packages\\keras\\engine\\training.py\", line 1790, in test_step\n      self.compute_loss(x, y, y_pred, sample_weight)\n    File \"C:\\Python310\\lib\\site-packages\\keras\\engine\\training.py\", line 1109, in compute_loss\n      return self.compiled_loss(\n    File \"C:\\Python310\\lib\\site-packages\\keras\\engine\\compile_utils.py\", line 265, in __call__\n      loss_value = loss_obj(y_t, y_p, sample_weight=sw)\n    File \"C:\\Python310\\lib\\site-packages\\keras\\losses.py\", line 142, in __call__\n      losses = call_fn(y_true, y_pred)\n    File \"C:\\Python310\\lib\\site-packages\\keras\\losses.py\", line 268, in call\n      return ag_fn(y_true, y_pred, **self._fn_kwargs)\n    File \"C:\\Python310\\lib\\site-packages\\keras\\losses.py\", line 1984, in categorical_crossentropy\n      return backend.categorical_crossentropy(\n    File \"C:\\Python310\\lib\\site-packages\\keras\\backend.py\", line 5565, in categorical_crossentropy\n      return tf.nn.softmax_cross_entropy_with_logits(\nNode: 'categorical_crossentropy/softmax_cross_entropy_with_logits'\nlogits and labels must be broadcastable: logits_size=[32,36] labels_size=[32,37]\n\t [[{{node categorical_crossentropy/softmax_cross_entropy_with_logits}}]] [Op:__inference_test_function_1835]",
     "output_type": "error",
     "traceback": [
      "\u001b[1;31m---------------------------------------------------------------------------\u001b[0m",
      "\u001b[1;31mInvalidArgumentError\u001b[0m                      Traceback (most recent call last)",
      "Cell \u001b[1;32mIn[5], line 86\u001b[0m\n\u001b[0;32m     77\u001b[0m model\u001b[38;5;241m.\u001b[39mfit_generator(\n\u001b[0;32m     78\u001b[0m     train_data,\n\u001b[0;32m     79\u001b[0m     steps_per_epoch\u001b[38;5;241m=\u001b[39m\u001b[38;5;28mlen\u001b[39m(train_data),\n\u001b[1;32m   (...)\u001b[0m\n\u001b[0;32m     82\u001b[0m     validation_steps\u001b[38;5;241m=\u001b[39m\u001b[38;5;28mlen\u001b[39m(validation_data)\n\u001b[0;32m     83\u001b[0m )\n\u001b[0;32m     85\u001b[0m \u001b[38;5;66;03m# Evaluate the model:\u001b[39;00m\n\u001b[1;32m---> 86\u001b[0m score \u001b[38;5;241m=\u001b[39m \u001b[43mmodel\u001b[49m\u001b[38;5;241;43m.\u001b[39;49m\u001b[43mevaluate_generator\u001b[49m\u001b[43m(\u001b[49m\n\u001b[0;32m     87\u001b[0m \u001b[43m    \u001b[49m\u001b[43mtesting_data\u001b[49m\u001b[43m,\u001b[49m\n\u001b[0;32m     88\u001b[0m \u001b[43m    \u001b[49m\u001b[43msteps\u001b[49m\u001b[38;5;241;43m=\u001b[39;49m\u001b[38;5;28;43mlen\u001b[39;49m\u001b[43m(\u001b[49m\u001b[43mtesting_data\u001b[49m\u001b[43m)\u001b[49m\n\u001b[0;32m     89\u001b[0m \u001b[43m)\u001b[49m\n\u001b[0;32m     91\u001b[0m \u001b[38;5;28mprint\u001b[39m(\u001b[38;5;124m'\u001b[39m\u001b[38;5;124mTest loss:\u001b[39m\u001b[38;5;124m'\u001b[39m, score[\u001b[38;5;241m0\u001b[39m])\n\u001b[0;32m     92\u001b[0m \u001b[38;5;28mprint\u001b[39m(\u001b[38;5;124m'\u001b[39m\u001b[38;5;124mTest accuracy:\u001b[39m\u001b[38;5;124m'\u001b[39m, score[\u001b[38;5;241m1\u001b[39m])\n",
      "File \u001b[1;32mC:\\Python310\\lib\\site-packages\\keras\\engine\\training.py:2678\u001b[0m, in \u001b[0;36mModel.evaluate_generator\u001b[1;34m(self, generator, steps, callbacks, max_queue_size, workers, use_multiprocessing, verbose)\u001b[0m\n\u001b[0;32m   2670\u001b[0m warnings\u001b[38;5;241m.\u001b[39mwarn(\n\u001b[0;32m   2671\u001b[0m     \u001b[38;5;124m\"\u001b[39m\u001b[38;5;124m`Model.evaluate_generator` is deprecated and \u001b[39m\u001b[38;5;124m\"\u001b[39m\n\u001b[0;32m   2672\u001b[0m     \u001b[38;5;124m\"\u001b[39m\u001b[38;5;124mwill be removed in a future version. \u001b[39m\u001b[38;5;124m\"\u001b[39m\n\u001b[0;32m   2673\u001b[0m     \u001b[38;5;124m\"\u001b[39m\u001b[38;5;124mPlease use `Model.evaluate`, which supports generators.\u001b[39m\u001b[38;5;124m\"\u001b[39m,\n\u001b[0;32m   2674\u001b[0m     stacklevel\u001b[38;5;241m=\u001b[39m\u001b[38;5;241m2\u001b[39m,\n\u001b[0;32m   2675\u001b[0m )\n\u001b[0;32m   2676\u001b[0m \u001b[38;5;28mself\u001b[39m\u001b[38;5;241m.\u001b[39m_check_call_args(\u001b[38;5;124m\"\u001b[39m\u001b[38;5;124mevaluate_generator\u001b[39m\u001b[38;5;124m\"\u001b[39m)\n\u001b[1;32m-> 2678\u001b[0m \u001b[38;5;28;01mreturn\u001b[39;00m \u001b[38;5;28;43mself\u001b[39;49m\u001b[38;5;241;43m.\u001b[39;49m\u001b[43mevaluate\u001b[49m\u001b[43m(\u001b[49m\n\u001b[0;32m   2679\u001b[0m \u001b[43m    \u001b[49m\u001b[43mgenerator\u001b[49m\u001b[43m,\u001b[49m\n\u001b[0;32m   2680\u001b[0m \u001b[43m    \u001b[49m\u001b[43msteps\u001b[49m\u001b[38;5;241;43m=\u001b[39;49m\u001b[43msteps\u001b[49m\u001b[43m,\u001b[49m\n\u001b[0;32m   2681\u001b[0m \u001b[43m    \u001b[49m\u001b[43mmax_queue_size\u001b[49m\u001b[38;5;241;43m=\u001b[39;49m\u001b[43mmax_queue_size\u001b[49m\u001b[43m,\u001b[49m\n\u001b[0;32m   2682\u001b[0m \u001b[43m    \u001b[49m\u001b[43mworkers\u001b[49m\u001b[38;5;241;43m=\u001b[39;49m\u001b[43mworkers\u001b[49m\u001b[43m,\u001b[49m\n\u001b[0;32m   2683\u001b[0m \u001b[43m    \u001b[49m\u001b[43muse_multiprocessing\u001b[49m\u001b[38;5;241;43m=\u001b[39;49m\u001b[43muse_multiprocessing\u001b[49m\u001b[43m,\u001b[49m\n\u001b[0;32m   2684\u001b[0m \u001b[43m    \u001b[49m\u001b[43mverbose\u001b[49m\u001b[38;5;241;43m=\u001b[39;49m\u001b[43mverbose\u001b[49m\u001b[43m,\u001b[49m\n\u001b[0;32m   2685\u001b[0m \u001b[43m    \u001b[49m\u001b[43mcallbacks\u001b[49m\u001b[38;5;241;43m=\u001b[39;49m\u001b[43mcallbacks\u001b[49m\u001b[43m,\u001b[49m\n\u001b[0;32m   2686\u001b[0m \u001b[43m\u001b[49m\u001b[43m)\u001b[49m\n",
      "File \u001b[1;32mC:\\Python310\\lib\\site-packages\\keras\\utils\\traceback_utils.py:70\u001b[0m, in \u001b[0;36mfilter_traceback.<locals>.error_handler\u001b[1;34m(*args, **kwargs)\u001b[0m\n\u001b[0;32m     67\u001b[0m     filtered_tb \u001b[38;5;241m=\u001b[39m _process_traceback_frames(e\u001b[38;5;241m.\u001b[39m__traceback__)\n\u001b[0;32m     68\u001b[0m     \u001b[38;5;66;03m# To get the full stack trace, call:\u001b[39;00m\n\u001b[0;32m     69\u001b[0m     \u001b[38;5;66;03m# `tf.debugging.disable_traceback_filtering()`\u001b[39;00m\n\u001b[1;32m---> 70\u001b[0m     \u001b[38;5;28;01mraise\u001b[39;00m e\u001b[38;5;241m.\u001b[39mwith_traceback(filtered_tb) \u001b[38;5;28;01mfrom\u001b[39;00m \u001b[38;5;28;01mNone\u001b[39;00m\n\u001b[0;32m     71\u001b[0m \u001b[38;5;28;01mfinally\u001b[39;00m:\n\u001b[0;32m     72\u001b[0m     \u001b[38;5;28;01mdel\u001b[39;00m filtered_tb\n",
      "File \u001b[1;32mC:\\Python310\\lib\\site-packages\\tensorflow\\python\\eager\\execute.py:52\u001b[0m, in \u001b[0;36mquick_execute\u001b[1;34m(op_name, num_outputs, inputs, attrs, ctx, name)\u001b[0m\n\u001b[0;32m     50\u001b[0m \u001b[38;5;28;01mtry\u001b[39;00m:\n\u001b[0;32m     51\u001b[0m   ctx\u001b[38;5;241m.\u001b[39mensure_initialized()\n\u001b[1;32m---> 52\u001b[0m   tensors \u001b[38;5;241m=\u001b[39m pywrap_tfe\u001b[38;5;241m.\u001b[39mTFE_Py_Execute(ctx\u001b[38;5;241m.\u001b[39m_handle, device_name, op_name,\n\u001b[0;32m     53\u001b[0m                                       inputs, attrs, num_outputs)\n\u001b[0;32m     54\u001b[0m \u001b[38;5;28;01mexcept\u001b[39;00m core\u001b[38;5;241m.\u001b[39m_NotOkStatusException \u001b[38;5;28;01mas\u001b[39;00m e:\n\u001b[0;32m     55\u001b[0m   \u001b[38;5;28;01mif\u001b[39;00m name \u001b[38;5;129;01mis\u001b[39;00m \u001b[38;5;129;01mnot\u001b[39;00m \u001b[38;5;28;01mNone\u001b[39;00m:\n",
      "\u001b[1;31mInvalidArgumentError\u001b[0m: Graph execution error:\n\nDetected at node 'categorical_crossentropy/softmax_cross_entropy_with_logits' defined at (most recent call last):\n    File \"C:\\Python310\\lib\\runpy.py\", line 196, in _run_module_as_main\n      return _run_code(code, main_globals, None,\n    File \"C:\\Python310\\lib\\runpy.py\", line 86, in _run_code\n      exec(code, run_globals)\n    File \"C:\\Python310\\lib\\site-packages\\ipykernel_launcher.py\", line 17, in <module>\n      app.launch_new_instance()\n    File \"C:\\Python310\\lib\\site-packages\\traitlets\\config\\application.py\", line 1043, in launch_instance\n      app.start()\n    File \"C:\\Python310\\lib\\site-packages\\ipykernel\\kernelapp.py\", line 725, in start\n      self.io_loop.start()\n    File \"C:\\Python310\\lib\\site-packages\\tornado\\platform\\asyncio.py\", line 215, in start\n      self.asyncio_loop.run_forever()\n    File \"C:\\Python310\\lib\\asyncio\\base_events.py\", line 600, in run_forever\n      self._run_once()\n    File \"C:\\Python310\\lib\\asyncio\\base_events.py\", line 1896, in _run_once\n      handle._run()\n    File \"C:\\Python310\\lib\\asyncio\\events.py\", line 80, in _run\n      self._context.run(self._callback, *self._args)\n    File \"C:\\Python310\\lib\\site-packages\\ipykernel\\kernelbase.py\", line 513, in dispatch_queue\n      await self.process_one()\n    File \"C:\\Python310\\lib\\site-packages\\ipykernel\\kernelbase.py\", line 502, in process_one\n      await dispatch(*args)\n    File \"C:\\Python310\\lib\\site-packages\\ipykernel\\kernelbase.py\", line 409, in dispatch_shell\n      await result\n    File \"C:\\Python310\\lib\\site-packages\\ipykernel\\kernelbase.py\", line 729, in execute_request\n      reply_content = await reply_content\n    File \"C:\\Python310\\lib\\site-packages\\ipykernel\\ipkernel.py\", line 422, in do_execute\n      res = shell.run_cell(\n    File \"C:\\Python310\\lib\\site-packages\\ipykernel\\zmqshell.py\", line 540, in run_cell\n      return super().run_cell(*args, **kwargs)\n    File \"C:\\Python310\\lib\\site-packages\\IPython\\core\\interactiveshell.py\", line 3009, in run_cell\n      result = self._run_cell(\n    File \"C:\\Python310\\lib\\site-packages\\IPython\\core\\interactiveshell.py\", line 3064, in _run_cell\n      result = runner(coro)\n    File \"C:\\Python310\\lib\\site-packages\\IPython\\core\\async_helpers.py\", line 129, in _pseudo_sync_runner\n      coro.send(None)\n    File \"C:\\Python310\\lib\\site-packages\\IPython\\core\\interactiveshell.py\", line 3269, in run_cell_async\n      has_raised = await self.run_ast_nodes(code_ast.body, cell_name,\n    File \"C:\\Python310\\lib\\site-packages\\IPython\\core\\interactiveshell.py\", line 3448, in run_ast_nodes\n      if await self.run_code(code, result, async_=asy):\n    File \"C:\\Python310\\lib\\site-packages\\IPython\\core\\interactiveshell.py\", line 3508, in run_code\n      exec(code_obj, self.user_global_ns, self.user_ns)\n    File \"C:\\Users\\VARUN-PC\\AppData\\Local\\Temp\\ipykernel_21016\\746130139.py\", line 77, in <module>\n      model.fit_generator(\n    File \"C:\\Python310\\lib\\site-packages\\keras\\engine\\training.py\", line 2636, in fit_generator\n      return self.fit(\n    File \"C:\\Python310\\lib\\site-packages\\keras\\utils\\traceback_utils.py\", line 65, in error_handler\n      return fn(*args, **kwargs)\n    File \"C:\\Python310\\lib\\site-packages\\keras\\engine\\training.py\", line 1729, in fit\n      val_logs = self.evaluate(\n    File \"C:\\Python310\\lib\\site-packages\\keras\\utils\\traceback_utils.py\", line 65, in error_handler\n      return fn(*args, **kwargs)\n    File \"C:\\Python310\\lib\\site-packages\\keras\\engine\\training.py\", line 2072, in evaluate\n      tmp_logs = self.test_function(iterator)\n    File \"C:\\Python310\\lib\\site-packages\\keras\\engine\\training.py\", line 1852, in test_function\n      return step_function(self, iterator)\n    File \"C:\\Python310\\lib\\site-packages\\keras\\engine\\training.py\", line 1836, in step_function\n      outputs = model.distribute_strategy.run(run_step, args=(data,))\n    File \"C:\\Python310\\lib\\site-packages\\keras\\engine\\training.py\", line 1824, in run_step\n      outputs = model.test_step(data)\n    File \"C:\\Python310\\lib\\site-packages\\keras\\engine\\training.py\", line 1790, in test_step\n      self.compute_loss(x, y, y_pred, sample_weight)\n    File \"C:\\Python310\\lib\\site-packages\\keras\\engine\\training.py\", line 1109, in compute_loss\n      return self.compiled_loss(\n    File \"C:\\Python310\\lib\\site-packages\\keras\\engine\\compile_utils.py\", line 265, in __call__\n      loss_value = loss_obj(y_t, y_p, sample_weight=sw)\n    File \"C:\\Python310\\lib\\site-packages\\keras\\losses.py\", line 142, in __call__\n      losses = call_fn(y_true, y_pred)\n    File \"C:\\Python310\\lib\\site-packages\\keras\\losses.py\", line 268, in call\n      return ag_fn(y_true, y_pred, **self._fn_kwargs)\n    File \"C:\\Python310\\lib\\site-packages\\keras\\losses.py\", line 1984, in categorical_crossentropy\n      return backend.categorical_crossentropy(\n    File \"C:\\Python310\\lib\\site-packages\\keras\\backend.py\", line 5565, in categorical_crossentropy\n      return tf.nn.softmax_cross_entropy_with_logits(\nNode: 'categorical_crossentropy/softmax_cross_entropy_with_logits'\nlogits and labels must be broadcastable: logits_size=[32,36] labels_size=[32,37]\n\t [[{{node categorical_crossentropy/softmax_cross_entropy_with_logits}}]] [Op:__inference_test_function_1835]"
     ]
    }
   ],
   "source": [
    "from tensorflow import keras\n",
    "from keras.models import Sequential\n",
    "from keras.layers import Conv2D, MaxPooling2D, Flatten, Dense\n",
    "\n",
    "# Create a list of the directories containing your training, validation, and testing datasets:\n",
    "training_dir = 'train/'\n",
    "validation_dir = 'validation/'\n",
    "testing_dir = 'test/'\n",
    "\n",
    "# Create a list of the labels for each class in your dataset:\n",
    "classes = ['apple','banana','beetroot','bell pepper','cabbage','capsicum','carrot','cauliflower','chilli pepper','corn','cucumber','eggplant','garlic','ginger','grapes','jalepeno','kiwi','lemon','lettuce','mango','onion','orange','paprika','pear','peas','pineapple','pomegranate','potato','raddish','soy beans','spinach','sweetcorn','sweetpotato','tomato','turnip','watermelon']\n",
    "\n",
    "# Create a generator for the training dataset:\n",
    "train_generator = keras.preprocessing.image.ImageDataGenerator(\n",
    "    rescale=1./255,\n",
    "    rotation_range=40,\n",
    "    width_shift_range=0.2,\n",
    "    height_shift_range=0.2,\n",
    "    horizontal_flip=True,\n",
    "    vertical_flip=True,\n",
    "    fill_mode='nearest'\n",
    ")\n",
    "\n",
    "train_data = train_generator.flow_from_directory(\n",
    "    training_dir,\n",
    "    target_size=(224, 224),\n",
    "    batch_size=32,\n",
    "    class_mode='categorical',\n",
    "    shuffle=True\n",
    ")\n",
    "\n",
    "# Create a generator for the validation dataset:\n",
    "validation_generator = keras.preprocessing.image.ImageDataGenerator(\n",
    "    rescale=1./255\n",
    ")\n",
    "\n",
    "validation_data = validation_generator.flow_from_directory(\n",
    "    validation_dir,\n",
    "    target_size=(224, 224),\n",
    "    batch_size=32,\n",
    "    class_mode='categorical',\n",
    "    shuffle=False\n",
    ")\n",
    "\n",
    "# Create a generator for the testing dataset:\n",
    "testing_generator = keras.preprocessing.image.ImageDataGenerator(\n",
    "    rescale=1./255\n",
    ")\n",
    "\n",
    "testing_data = testing_generator.flow_from_directory(\n",
    "    testing_dir,\n",
    "    target_size=(224, 224),\n",
    "    batch_size=32,\n",
    "    class_mode='categorical',\n",
    "    shuffle=False\n",
    ")\n",
    "\n",
    "# Define the model architecture:\n",
    "model = Sequential()\n",
    "\n",
    "model.add(Conv2D(32, (3, 3), padding='same',\n",
    "          activation='relu', input_shape=(224, 224, 3)))\n",
    "model.add(MaxPooling2D((2, 2), strides=(2, 2)))\n",
    "\n",
    "model.add(Conv2D(64, (3, 3), padding='same', activation='relu'))\n",
    "model.add(MaxPooling2D((2, 2), strides=(2, 2)))\n",
    "\n",
    "model.add(Flatten())\n",
    "model.add(Dense(128, activation='relu'))\n",
    "model.add(Dense(len(classes), activation='softmax'))\n",
    "\n",
    "# Compile the model:\n",
    "model.compile(loss='categorical_crossentropy',\n",
    "              optimizer='adam', metrics=['accuracy'])\n",
    "\n",
    "# Train the model:\n",
    "model.fit_generator(\n",
    "    train_data,\n",
    "    steps_per_epoch=len(train_data),\n",
    "    epochs=10,\n",
    "    validation_data=validation_data,\n",
    "    validation_steps=len(validation_data)\n",
    ")\n",
    "\n",
    "# Evaluate the model:\n",
    "score = model.evaluate_generator(\n",
    "    testing_data,\n",
    "    steps=len(testing_data)\n",
    ")\n",
    "\n",
    "print('Test loss:', score[0])\n",
    "print('Test accuracy:', score[1])\n",
    "\n",
    "# Save the model:\n",
    "model.save('model1.h5')\n",
    "\n"
   ]
  },
  {
   "cell_type": "code",
   "execution_count": 7,
   "id": "38cb62c4",
   "metadata": {},
   "outputs": [
    {
     "ename": "InvalidArgumentError",
     "evalue": "Graph execution error:\n\nDetected at node 'categorical_crossentropy/softmax_cross_entropy_with_logits' defined at (most recent call last):\n    File \"C:\\Python310\\lib\\runpy.py\", line 196, in _run_module_as_main\n      return _run_code(code, main_globals, None,\n    File \"C:\\Python310\\lib\\runpy.py\", line 86, in _run_code\n      exec(code, run_globals)\n    File \"C:\\Python310\\lib\\site-packages\\ipykernel_launcher.py\", line 17, in <module>\n      app.launch_new_instance()\n    File \"C:\\Python310\\lib\\site-packages\\traitlets\\config\\application.py\", line 1043, in launch_instance\n      app.start()\n    File \"C:\\Python310\\lib\\site-packages\\ipykernel\\kernelapp.py\", line 725, in start\n      self.io_loop.start()\n    File \"C:\\Python310\\lib\\site-packages\\tornado\\platform\\asyncio.py\", line 215, in start\n      self.asyncio_loop.run_forever()\n    File \"C:\\Python310\\lib\\asyncio\\base_events.py\", line 600, in run_forever\n      self._run_once()\n    File \"C:\\Python310\\lib\\asyncio\\base_events.py\", line 1896, in _run_once\n      handle._run()\n    File \"C:\\Python310\\lib\\asyncio\\events.py\", line 80, in _run\n      self._context.run(self._callback, *self._args)\n    File \"C:\\Python310\\lib\\site-packages\\ipykernel\\kernelbase.py\", line 513, in dispatch_queue\n      await self.process_one()\n    File \"C:\\Python310\\lib\\site-packages\\ipykernel\\kernelbase.py\", line 502, in process_one\n      await dispatch(*args)\n    File \"C:\\Python310\\lib\\site-packages\\ipykernel\\kernelbase.py\", line 409, in dispatch_shell\n      await result\n    File \"C:\\Python310\\lib\\site-packages\\ipykernel\\kernelbase.py\", line 729, in execute_request\n      reply_content = await reply_content\n    File \"C:\\Python310\\lib\\site-packages\\ipykernel\\ipkernel.py\", line 422, in do_execute\n      res = shell.run_cell(\n    File \"C:\\Python310\\lib\\site-packages\\ipykernel\\zmqshell.py\", line 540, in run_cell\n      return super().run_cell(*args, **kwargs)\n    File \"C:\\Python310\\lib\\site-packages\\IPython\\core\\interactiveshell.py\", line 3009, in run_cell\n      result = self._run_cell(\n    File \"C:\\Python310\\lib\\site-packages\\IPython\\core\\interactiveshell.py\", line 3064, in _run_cell\n      result = runner(coro)\n    File \"C:\\Python310\\lib\\site-packages\\IPython\\core\\async_helpers.py\", line 129, in _pseudo_sync_runner\n      coro.send(None)\n    File \"C:\\Python310\\lib\\site-packages\\IPython\\core\\interactiveshell.py\", line 3269, in run_cell_async\n      has_raised = await self.run_ast_nodes(code_ast.body, cell_name,\n    File \"C:\\Python310\\lib\\site-packages\\IPython\\core\\interactiveshell.py\", line 3448, in run_ast_nodes\n      if await self.run_code(code, result, async_=asy):\n    File \"C:\\Python310\\lib\\site-packages\\IPython\\core\\interactiveshell.py\", line 3508, in run_code\n      exec(code_obj, self.user_global_ns, self.user_ns)\n    File \"C:\\Users\\VARUN-PC\\AppData\\Local\\Temp\\ipykernel_21016\\746130139.py\", line 77, in <module>\n      model.fit_generator(\n    File \"C:\\Python310\\lib\\site-packages\\keras\\engine\\training.py\", line 2636, in fit_generator\n      return self.fit(\n    File \"C:\\Python310\\lib\\site-packages\\keras\\utils\\traceback_utils.py\", line 65, in error_handler\n      return fn(*args, **kwargs)\n    File \"C:\\Python310\\lib\\site-packages\\keras\\engine\\training.py\", line 1729, in fit\n      val_logs = self.evaluate(\n    File \"C:\\Python310\\lib\\site-packages\\keras\\utils\\traceback_utils.py\", line 65, in error_handler\n      return fn(*args, **kwargs)\n    File \"C:\\Python310\\lib\\site-packages\\keras\\engine\\training.py\", line 2072, in evaluate\n      tmp_logs = self.test_function(iterator)\n    File \"C:\\Python310\\lib\\site-packages\\keras\\engine\\training.py\", line 1852, in test_function\n      return step_function(self, iterator)\n    File \"C:\\Python310\\lib\\site-packages\\keras\\engine\\training.py\", line 1836, in step_function\n      outputs = model.distribute_strategy.run(run_step, args=(data,))\n    File \"C:\\Python310\\lib\\site-packages\\keras\\engine\\training.py\", line 1824, in run_step\n      outputs = model.test_step(data)\n    File \"C:\\Python310\\lib\\site-packages\\keras\\engine\\training.py\", line 1790, in test_step\n      self.compute_loss(x, y, y_pred, sample_weight)\n    File \"C:\\Python310\\lib\\site-packages\\keras\\engine\\training.py\", line 1109, in compute_loss\n      return self.compiled_loss(\n    File \"C:\\Python310\\lib\\site-packages\\keras\\engine\\compile_utils.py\", line 265, in __call__\n      loss_value = loss_obj(y_t, y_p, sample_weight=sw)\n    File \"C:\\Python310\\lib\\site-packages\\keras\\losses.py\", line 142, in __call__\n      losses = call_fn(y_true, y_pred)\n    File \"C:\\Python310\\lib\\site-packages\\keras\\losses.py\", line 268, in call\n      return ag_fn(y_true, y_pred, **self._fn_kwargs)\n    File \"C:\\Python310\\lib\\site-packages\\keras\\losses.py\", line 1984, in categorical_crossentropy\n      return backend.categorical_crossentropy(\n    File \"C:\\Python310\\lib\\site-packages\\keras\\backend.py\", line 5565, in categorical_crossentropy\n      return tf.nn.softmax_cross_entropy_with_logits(\nNode: 'categorical_crossentropy/softmax_cross_entropy_with_logits'\nlogits and labels must be broadcastable: logits_size=[32,36] labels_size=[32,37]\n\t [[{{node categorical_crossentropy/softmax_cross_entropy_with_logits}}]] [Op:__inference_test_function_1835]",
     "output_type": "error",
     "traceback": [
      "\u001b[1;31m---------------------------------------------------------------------------\u001b[0m",
      "\u001b[1;31mInvalidArgumentError\u001b[0m                      Traceback (most recent call last)",
      "Cell \u001b[1;32mIn[7], line 2\u001b[0m\n\u001b[0;32m      1\u001b[0m \u001b[38;5;66;03m# Evaluate the model:\u001b[39;00m\n\u001b[1;32m----> 2\u001b[0m score \u001b[38;5;241m=\u001b[39m \u001b[43mmodel\u001b[49m\u001b[38;5;241;43m.\u001b[39;49m\u001b[43mevaluate\u001b[49m\u001b[43m(\u001b[49m\n\u001b[0;32m      3\u001b[0m \u001b[43m    \u001b[49m\u001b[43mtesting_data\u001b[49m\u001b[43m,\u001b[49m\n\u001b[0;32m      4\u001b[0m \u001b[43m    \u001b[49m\u001b[43msteps\u001b[49m\u001b[38;5;241;43m=\u001b[39;49m\u001b[38;5;28;43mlen\u001b[39;49m\u001b[43m(\u001b[49m\u001b[43mtesting_data\u001b[49m\u001b[43m)\u001b[49m\n\u001b[0;32m      5\u001b[0m \u001b[43m)\u001b[49m\n\u001b[0;32m      7\u001b[0m \u001b[38;5;28mprint\u001b[39m(\u001b[38;5;124m'\u001b[39m\u001b[38;5;124mTest loss:\u001b[39m\u001b[38;5;124m'\u001b[39m, score[\u001b[38;5;241m0\u001b[39m])\n\u001b[0;32m      8\u001b[0m \u001b[38;5;28mprint\u001b[39m(\u001b[38;5;124m'\u001b[39m\u001b[38;5;124mTest accuracy:\u001b[39m\u001b[38;5;124m'\u001b[39m, score[\u001b[38;5;241m1\u001b[39m])\n",
      "File \u001b[1;32mC:\\Python310\\lib\\site-packages\\keras\\utils\\traceback_utils.py:70\u001b[0m, in \u001b[0;36mfilter_traceback.<locals>.error_handler\u001b[1;34m(*args, **kwargs)\u001b[0m\n\u001b[0;32m     67\u001b[0m     filtered_tb \u001b[38;5;241m=\u001b[39m _process_traceback_frames(e\u001b[38;5;241m.\u001b[39m__traceback__)\n\u001b[0;32m     68\u001b[0m     \u001b[38;5;66;03m# To get the full stack trace, call:\u001b[39;00m\n\u001b[0;32m     69\u001b[0m     \u001b[38;5;66;03m# `tf.debugging.disable_traceback_filtering()`\u001b[39;00m\n\u001b[1;32m---> 70\u001b[0m     \u001b[38;5;28;01mraise\u001b[39;00m e\u001b[38;5;241m.\u001b[39mwith_traceback(filtered_tb) \u001b[38;5;28;01mfrom\u001b[39;00m \u001b[38;5;28;01mNone\u001b[39;00m\n\u001b[0;32m     71\u001b[0m \u001b[38;5;28;01mfinally\u001b[39;00m:\n\u001b[0;32m     72\u001b[0m     \u001b[38;5;28;01mdel\u001b[39;00m filtered_tb\n",
      "File \u001b[1;32mC:\\Python310\\lib\\site-packages\\tensorflow\\python\\eager\\execute.py:52\u001b[0m, in \u001b[0;36mquick_execute\u001b[1;34m(op_name, num_outputs, inputs, attrs, ctx, name)\u001b[0m\n\u001b[0;32m     50\u001b[0m \u001b[38;5;28;01mtry\u001b[39;00m:\n\u001b[0;32m     51\u001b[0m   ctx\u001b[38;5;241m.\u001b[39mensure_initialized()\n\u001b[1;32m---> 52\u001b[0m   tensors \u001b[38;5;241m=\u001b[39m pywrap_tfe\u001b[38;5;241m.\u001b[39mTFE_Py_Execute(ctx\u001b[38;5;241m.\u001b[39m_handle, device_name, op_name,\n\u001b[0;32m     53\u001b[0m                                       inputs, attrs, num_outputs)\n\u001b[0;32m     54\u001b[0m \u001b[38;5;28;01mexcept\u001b[39;00m core\u001b[38;5;241m.\u001b[39m_NotOkStatusException \u001b[38;5;28;01mas\u001b[39;00m e:\n\u001b[0;32m     55\u001b[0m   \u001b[38;5;28;01mif\u001b[39;00m name \u001b[38;5;129;01mis\u001b[39;00m \u001b[38;5;129;01mnot\u001b[39;00m \u001b[38;5;28;01mNone\u001b[39;00m:\n",
      "\u001b[1;31mInvalidArgumentError\u001b[0m: Graph execution error:\n\nDetected at node 'categorical_crossentropy/softmax_cross_entropy_with_logits' defined at (most recent call last):\n    File \"C:\\Python310\\lib\\runpy.py\", line 196, in _run_module_as_main\n      return _run_code(code, main_globals, None,\n    File \"C:\\Python310\\lib\\runpy.py\", line 86, in _run_code\n      exec(code, run_globals)\n    File \"C:\\Python310\\lib\\site-packages\\ipykernel_launcher.py\", line 17, in <module>\n      app.launch_new_instance()\n    File \"C:\\Python310\\lib\\site-packages\\traitlets\\config\\application.py\", line 1043, in launch_instance\n      app.start()\n    File \"C:\\Python310\\lib\\site-packages\\ipykernel\\kernelapp.py\", line 725, in start\n      self.io_loop.start()\n    File \"C:\\Python310\\lib\\site-packages\\tornado\\platform\\asyncio.py\", line 215, in start\n      self.asyncio_loop.run_forever()\n    File \"C:\\Python310\\lib\\asyncio\\base_events.py\", line 600, in run_forever\n      self._run_once()\n    File \"C:\\Python310\\lib\\asyncio\\base_events.py\", line 1896, in _run_once\n      handle._run()\n    File \"C:\\Python310\\lib\\asyncio\\events.py\", line 80, in _run\n      self._context.run(self._callback, *self._args)\n    File \"C:\\Python310\\lib\\site-packages\\ipykernel\\kernelbase.py\", line 513, in dispatch_queue\n      await self.process_one()\n    File \"C:\\Python310\\lib\\site-packages\\ipykernel\\kernelbase.py\", line 502, in process_one\n      await dispatch(*args)\n    File \"C:\\Python310\\lib\\site-packages\\ipykernel\\kernelbase.py\", line 409, in dispatch_shell\n      await result\n    File \"C:\\Python310\\lib\\site-packages\\ipykernel\\kernelbase.py\", line 729, in execute_request\n      reply_content = await reply_content\n    File \"C:\\Python310\\lib\\site-packages\\ipykernel\\ipkernel.py\", line 422, in do_execute\n      res = shell.run_cell(\n    File \"C:\\Python310\\lib\\site-packages\\ipykernel\\zmqshell.py\", line 540, in run_cell\n      return super().run_cell(*args, **kwargs)\n    File \"C:\\Python310\\lib\\site-packages\\IPython\\core\\interactiveshell.py\", line 3009, in run_cell\n      result = self._run_cell(\n    File \"C:\\Python310\\lib\\site-packages\\IPython\\core\\interactiveshell.py\", line 3064, in _run_cell\n      result = runner(coro)\n    File \"C:\\Python310\\lib\\site-packages\\IPython\\core\\async_helpers.py\", line 129, in _pseudo_sync_runner\n      coro.send(None)\n    File \"C:\\Python310\\lib\\site-packages\\IPython\\core\\interactiveshell.py\", line 3269, in run_cell_async\n      has_raised = await self.run_ast_nodes(code_ast.body, cell_name,\n    File \"C:\\Python310\\lib\\site-packages\\IPython\\core\\interactiveshell.py\", line 3448, in run_ast_nodes\n      if await self.run_code(code, result, async_=asy):\n    File \"C:\\Python310\\lib\\site-packages\\IPython\\core\\interactiveshell.py\", line 3508, in run_code\n      exec(code_obj, self.user_global_ns, self.user_ns)\n    File \"C:\\Users\\VARUN-PC\\AppData\\Local\\Temp\\ipykernel_21016\\746130139.py\", line 77, in <module>\n      model.fit_generator(\n    File \"C:\\Python310\\lib\\site-packages\\keras\\engine\\training.py\", line 2636, in fit_generator\n      return self.fit(\n    File \"C:\\Python310\\lib\\site-packages\\keras\\utils\\traceback_utils.py\", line 65, in error_handler\n      return fn(*args, **kwargs)\n    File \"C:\\Python310\\lib\\site-packages\\keras\\engine\\training.py\", line 1729, in fit\n      val_logs = self.evaluate(\n    File \"C:\\Python310\\lib\\site-packages\\keras\\utils\\traceback_utils.py\", line 65, in error_handler\n      return fn(*args, **kwargs)\n    File \"C:\\Python310\\lib\\site-packages\\keras\\engine\\training.py\", line 2072, in evaluate\n      tmp_logs = self.test_function(iterator)\n    File \"C:\\Python310\\lib\\site-packages\\keras\\engine\\training.py\", line 1852, in test_function\n      return step_function(self, iterator)\n    File \"C:\\Python310\\lib\\site-packages\\keras\\engine\\training.py\", line 1836, in step_function\n      outputs = model.distribute_strategy.run(run_step, args=(data,))\n    File \"C:\\Python310\\lib\\site-packages\\keras\\engine\\training.py\", line 1824, in run_step\n      outputs = model.test_step(data)\n    File \"C:\\Python310\\lib\\site-packages\\keras\\engine\\training.py\", line 1790, in test_step\n      self.compute_loss(x, y, y_pred, sample_weight)\n    File \"C:\\Python310\\lib\\site-packages\\keras\\engine\\training.py\", line 1109, in compute_loss\n      return self.compiled_loss(\n    File \"C:\\Python310\\lib\\site-packages\\keras\\engine\\compile_utils.py\", line 265, in __call__\n      loss_value = loss_obj(y_t, y_p, sample_weight=sw)\n    File \"C:\\Python310\\lib\\site-packages\\keras\\losses.py\", line 142, in __call__\n      losses = call_fn(y_true, y_pred)\n    File \"C:\\Python310\\lib\\site-packages\\keras\\losses.py\", line 268, in call\n      return ag_fn(y_true, y_pred, **self._fn_kwargs)\n    File \"C:\\Python310\\lib\\site-packages\\keras\\losses.py\", line 1984, in categorical_crossentropy\n      return backend.categorical_crossentropy(\n    File \"C:\\Python310\\lib\\site-packages\\keras\\backend.py\", line 5565, in categorical_crossentropy\n      return tf.nn.softmax_cross_entropy_with_logits(\nNode: 'categorical_crossentropy/softmax_cross_entropy_with_logits'\nlogits and labels must be broadcastable: logits_size=[32,36] labels_size=[32,37]\n\t [[{{node categorical_crossentropy/softmax_cross_entropy_with_logits}}]] [Op:__inference_test_function_1835]"
     ]
    }
   ],
   "source": [
    "# Evaluate the model:\n",
    "score = model.evaluate(\n",
    "    testing_data,\n",
    "    steps=len(testing_data)\n",
    ")\n",
    "\n",
    "print('Test loss:', score[0])\n",
    "print('Test accuracy:', score[1])\n",
    "\n",
    "# Save the model:\n",
    "model.save('model1.h5')"
   ]
  },
  {
   "cell_type": "code",
   "execution_count": 10,
   "id": "dabe6ec1",
   "metadata": {},
   "outputs": [
    {
     "data": {
      "text/plain": [
       "36"
      ]
     },
     "execution_count": 10,
     "metadata": {},
     "output_type": "execute_result"
    }
   ],
   "source": [
    "len(classes)"
   ]
  },
  {
   "cell_type": "code",
   "execution_count": 13,
   "id": "1b1d7a53",
   "metadata": {},
   "outputs": [
    {
     "name": "stdout",
     "output_type": "stream",
     "text": [
      "Found 3055 images belonging to 36 classes.\n",
      "Found 351 images belonging to 36 classes.\n",
      "Found 359 images belonging to 36 classes.\n"
     ]
    },
    {
     "name": "stderr",
     "output_type": "stream",
     "text": [
      "C:\\Users\\VARUN-PC\\AppData\\Local\\Temp\\ipykernel_21016\\3837691098.py:86: UserWarning: `Model.evaluate_generator` is deprecated and will be removed in a future version. Please use `Model.evaluate`, which supports generators.\n",
      "  score = model.evaluate_generator(\n"
     ]
    },
    {
     "name": "stdout",
     "output_type": "stream",
     "text": [
      "Test loss: 3.594731092453003\n",
      "Test accuracy: 0.027855154126882553\n"
     ]
    }
   ],
   "source": [
    "from tensorflow import keras\n",
    "from keras.models import Sequential\n",
    "from keras.layers import Conv2D, MaxPooling2D, Flatten, Dense\n",
    "\n",
    "# Create a list of the directories containing your training, validation, and testing datasets:\n",
    "training_dir = 'train/'\n",
    "validation_dir = 'validation/'\n",
    "testing_dir = 'test/'\n",
    "\n",
    "# Create a list of the labels for each class in your dataset:\n",
    "classes = ['apple','banana','beetroot','bell pepper','cabbage','capsicum','carrot','cauliflower','chilli pepper','corn','cucumber','eggplant','garlic','ginger','grapes','jalepeno','kiwi','lemon','lettuce','mango','onion','orange','paprika','pear','peas','pineapple','pomegranate','potato','raddish','soy beans','spinach','sweetcorn','sweetpotato','tomato','turnip','watermelon']\n",
    "\n",
    "# Create a generator for the training dataset:\n",
    "train_generator = keras.preprocessing.image.ImageDataGenerator(\n",
    "    rescale=1./255,\n",
    "    rotation_range=40,\n",
    "    width_shift_range=0.2,\n",
    "    height_shift_range=0.2,\n",
    "    horizontal_flip=True,\n",
    "    vertical_flip=True,\n",
    "    fill_mode='nearest'\n",
    ")\n",
    "\n",
    "train_data = train_generator.flow_from_directory(\n",
    "    training_dir,\n",
    "    target_size=(224, 224),\n",
    "    batch_size=32,\n",
    "    class_mode='categorical',\n",
    "    shuffle=True\n",
    ")\n",
    "\n",
    "# Create a generator for the validation dataset:\n",
    "validation_generator = keras.preprocessing.image.ImageDataGenerator(\n",
    "    rescale=1./255\n",
    ")\n",
    "\n",
    "validation_data = validation_generator.flow_from_directory(\n",
    "    validation_dir,\n",
    "    target_size=(224, 224),\n",
    "    batch_size=32,\n",
    "    class_mode='categorical',\n",
    "    shuffle=False\n",
    ")\n",
    "\n",
    "# Create a generator for the testing dataset:\n",
    "testing_generator = keras.preprocessing.image.ImageDataGenerator(\n",
    "    rescale=1./255\n",
    ")\n",
    "\n",
    "testing_data = testing_generator.flow_from_directory(\n",
    "    testing_dir,\n",
    "    target_size=(224, 224),\n",
    "    batch_size=32,\n",
    "    class_mode='categorical',\n",
    "    shuffle=False\n",
    ")\n",
    "\n",
    "# Define the model architecture:\n",
    "model = Sequential()\n",
    "\n",
    "model.add(Conv2D(32, (3, 3), padding='same',\n",
    "          activation='relu', input_shape=(224, 224, 3)))\n",
    "model.add(MaxPooling2D((2, 2), strides=(2, 2)))\n",
    "\n",
    "model.add(Conv2D(64, (3, 3), padding='same', activation='relu'))\n",
    "model.add(MaxPooling2D((2, 2), strides=(2, 2)))\n",
    "\n",
    "model.add(Flatten())\n",
    "model.add(Dense(128, activation='relu'))\n",
    "model.add(Dense(len(classes), activation='softmax'))\n",
    "\n",
    "# Compile the model:\n",
    "model.compile(loss='categorical_crossentropy',\n",
    "              optimizer='adam', metrics=['accuracy'])\n",
    "\n",
    "# Train the model:\n",
    "# model.fit_generator(\n",
    "#     train_data,\n",
    "#     steps_per_epoch=len(train_data),\n",
    "#     epochs=10,\n",
    "#     validation_data=validation_data,\n",
    "#     validation_steps=len(validation_data)\n",
    "# )\n",
    "\n",
    "# Evaluate the model:\n",
    "score = model.evaluate_generator(\n",
    "    testing_data,\n",
    "    steps=len(testing_data)\n",
    ")\n",
    "\n",
    "print('Test loss:', score[0])\n",
    "print('Test accuracy:', score[1])\n",
    "\n",
    "# Save the model:\n",
    "model.save('model1.h5')\n",
    "\n"
   ]
  },
  {
   "cell_type": "code",
   "execution_count": 14,
   "id": "08cb84cb",
   "metadata": {},
   "outputs": [
    {
     "name": "stdout",
     "output_type": "stream",
     "text": [
      "12/12 [==============================] - 9s 789ms/step - loss: 3.5947 - accuracy: 0.0279\n",
      "Test loss: 3.594731092453003\n",
      "Test accuracy: 0.027855154126882553\n"
     ]
    }
   ],
   "source": [
    "# Evaluate the model:\n",
    "score = model.evaluate(\n",
    "    testing_data,\n",
    "    steps=len(testing_data)\n",
    ")\n",
    "\n",
    "print('Test loss:', score[0])\n",
    "print('Test accuracy:', score[1])\n",
    "\n",
    "# Save the model:\n",
    "model.save('model1.h5')"
   ]
  },
  {
   "cell_type": "code",
   "execution_count": null,
   "id": "8a3991dd",
   "metadata": {},
   "outputs": [],
   "source": []
  }
 ],
 "metadata": {
  "kernelspec": {
   "display_name": "Python 3 (ipykernel)",
   "language": "python",
   "name": "python3"
  },
  "language_info": {
   "codemirror_mode": {
    "name": "ipython",
    "version": 3
   },
   "file_extension": ".py",
   "mimetype": "text/x-python",
   "name": "python",
   "nbconvert_exporter": "python",
   "pygments_lexer": "ipython3",
   "version": "3.10.4"
  }
 },
 "nbformat": 4,
 "nbformat_minor": 5
}
